Ignoring exception in command None:
discord.ext.commands.errors.CommandNotFound: Command "forfiet" is not found
Ignoring exception in command None:
discord.ext.commands.errors.CommandNotFound: Command "forfeit" is not found
Ignoring exception in command None:
discord.ext.commands.errors.CommandNotFound: Command "quit" is not found
Ignoring exception in command None:
discord.ext.commands.errors.CommandNotFound: Command "give" is not found
Ignoring exception in command join:
Traceback (most recent call last):
  File "/Users/benjamin/.pyenv/versions/3.9.0/lib/python3.9/site-packages/discord/ext/commands/bot.py", line 903, in invoke
    await ctx.command.invoke(ctx)
  File "/Users/benjamin/.pyenv/versions/3.9.0/lib/python3.9/site-packages/discord/ext/commands/core.py", line 851, in invoke
    await self.prepare(ctx)
  File "/Users/benjamin/.pyenv/versions/3.9.0/lib/python3.9/site-packages/discord/ext/commands/core.py", line 786, in prepare
    await self._parse_arguments(ctx)
  File "/Users/benjamin/.pyenv/versions/3.9.0/lib/python3.9/site-packages/discord/ext/commands/core.py", line 697, in _parse_arguments
    transformed = await self.transform(ctx, param)
  File "/Users/benjamin/.pyenv/versions/3.9.0/lib/python3.9/site-packages/discord/ext/commands/core.py", line 542, in transform
    raise MissingRequiredArgument(param)
discord.ext.commands.errors.MissingRequiredArgument: args is a required argument that is missing.
Ignoring exception in command debug:
Traceback (most recent call last):
  File "/Users/benjamin/.pyenv/versions/3.9.0/lib/python3.9/site-packages/discord/ext/commands/core.py", line 85, in wrapped
    ret = await coro(*args, **kwargs)
  File "/Users/benjamin/Documents/Developer/Python/ChessBot/chessbot_remastered.py", line 379, in debug
    await ctx.send("`{}\n{}`".format(data[guild][game_num], this_board))
KeyError: 0

The above exception was the direct cause of the following exception:

Traceback (most recent call last):
  File "/Users/benjamin/.pyenv/versions/3.9.0/lib/python3.9/site-packages/discord/ext/commands/bot.py", line 903, in invoke
    await ctx.command.invoke(ctx)
  File "/Users/benjamin/.pyenv/versions/3.9.0/lib/python3.9/site-packages/discord/ext/commands/core.py", line 859, in invoke
    await injected(*ctx.args, **ctx.kwargs)
  File "/Users/benjamin/.pyenv/versions/3.9.0/lib/python3.9/site-packages/discord/ext/commands/core.py", line 94, in wrapped
    raise CommandInvokeError(exc) from exc
discord.ext.commands.errors.CommandInvokeError: Command raised an exception: KeyError: 0
Ignoring exception in command debug:
Traceback (most recent call last):
  File "/Users/benjamin/.pyenv/versions/3.9.0/lib/python3.9/site-packages/discord/ext/commands/core.py", line 85, in wrapped
    ret = await coro(*args, **kwargs)
  File "/Users/benjamin/Documents/Developer/Python/ChessBot/chessbot_remastered.py", line 379, in debug
    await ctx.send("`{}\n{}`".format(data[guild][game_num], this_board))
KeyError: 0

The above exception was the direct cause of the following exception:

Traceback (most recent call last):
  File "/Users/benjamin/.pyenv/versions/3.9.0/lib/python3.9/site-packages/discord/ext/commands/bot.py", line 903, in invoke
    await ctx.command.invoke(ctx)
  File "/Users/benjamin/.pyenv/versions/3.9.0/lib/python3.9/site-packages/discord/ext/commands/core.py", line 859, in invoke
    await injected(*ctx.args, **ctx.kwargs)
  File "/Users/benjamin/.pyenv/versions/3.9.0/lib/python3.9/site-packages/discord/ext/commands/core.py", line 94, in wrapped
    raise CommandInvokeError(exc) from exc
discord.ext.commands.errors.CommandInvokeError: Command raised an exception: KeyError: 0
Ignoring exception in command debug:
Traceback (most recent call last):
  File "/Users/benjamin/.pyenv/versions/3.9.0/lib/python3.9/site-packages/discord/ext/commands/core.py", line 85, in wrapped
    ret = await coro(*args, **kwargs)
  File "/Users/benjamin/Documents/Developer/Python/ChessBot/chessbot_remastered.py", line 378, in debug
    this_board = chess.Board(data[guild][str(game_num)]["fen"])
KeyError: '-1'

The above exception was the direct cause of the following exception:

Traceback (most recent call last):
  File "/Users/benjamin/.pyenv/versions/3.9.0/lib/python3.9/site-packages/discord/ext/commands/bot.py", line 903, in invoke
    await ctx.command.invoke(ctx)
  File "/Users/benjamin/.pyenv/versions/3.9.0/lib/python3.9/site-packages/discord/ext/commands/core.py", line 859, in invoke
    await injected(*ctx.args, **ctx.kwargs)
  File "/Users/benjamin/.pyenv/versions/3.9.0/lib/python3.9/site-packages/discord/ext/commands/core.py", line 94, in wrapped
    raise CommandInvokeError(exc) from exc
discord.ext.commands.errors.CommandInvokeError: Command raised an exception: KeyError: '-1'
Ignoring exception in command None:
discord.ext.commands.errors.CommandNotFound: Command "nick" is not found
Ignoring exception in command None:
discord.ext.commands.errors.CommandNotFound: Command "nick" is not found
Ignoring exception in command None:
discord.ext.commands.errors.CommandNotFound: Command "nick" is not found
Ignoring exception in command None:
discord.ext.commands.errors.CommandNotFound: Command "nick" is not found
Ignoring exception in command None:
discord.ext.commands.errors.CommandNotFound: Command "nick" is not found
Ignoring exception in command None:
discord.ext.commands.errors.CommandNotFound: Command "nick" is not found
Traceback (most recent call last):
  File "/Users/benjamin/Documents/Developer/Python/ChessBot/chessbot_remastered.py", line 401, in <module>
    client.run(TOKEN)
  File "/Users/benjamin/.pyenv/versions/3.9.0/lib/python3.9/site-packages/discord/client.py", line 708, in run
    return future.result()
  File "/Users/benjamin/.pyenv/versions/3.9.0/lib/python3.9/site-packages/discord/client.py", line 687, in runner
    await self.start(*args, **kwargs)
  File "/Users/benjamin/.pyenv/versions/3.9.0/lib/python3.9/site-packages/discord/client.py", line 650, in start
    await self.login(*args, bot=bot)
  File "/Users/benjamin/.pyenv/versions/3.9.0/lib/python3.9/site-packages/discord/client.py", line 499, in login
    await self.http.static_login(token.strip(), bot=bot)
  File "/Users/benjamin/.pyenv/versions/3.9.0/lib/python3.9/site-packages/discord/http.py", line 291, in static_login
    data = await self.request(Route('GET', '/users/@me'))
  File "/Users/benjamin/.pyenv/versions/3.9.0/lib/python3.9/site-packages/discord/http.py", line 256, in request
    raise DiscordServerError(r, data)
discord.errors.DiscordServerError: 500 Internal Server Error (error code: 0): 500: Internal Server Error
Traceback (most recent call last):
  File "/Users/benjamin/Documents/Developer/Python/ChessBot/chessbot_remastered.py", line 401, in <module>
    client.run(TOKEN)
  File "/Users/benjamin/.pyenv/versions/3.9.0/lib/python3.9/site-packages/discord/client.py", line 708, in run
    return future.result()
  File "/Users/benjamin/.pyenv/versions/3.9.0/lib/python3.9/site-packages/discord/client.py", line 687, in runner
    await self.start(*args, **kwargs)
  File "/Users/benjamin/.pyenv/versions/3.9.0/lib/python3.9/site-packages/discord/client.py", line 650, in start
    await self.login(*args, bot=bot)
  File "/Users/benjamin/.pyenv/versions/3.9.0/lib/python3.9/site-packages/discord/client.py", line 499, in login
    await self.http.static_login(token.strip(), bot=bot)
  File "/Users/benjamin/.pyenv/versions/3.9.0/lib/python3.9/site-packages/discord/http.py", line 291, in static_login
    data = await self.request(Route('GET', '/users/@me'))
  File "/Users/benjamin/.pyenv/versions/3.9.0/lib/python3.9/site-packages/discord/http.py", line 256, in request
    raise DiscordServerError(r, data)
discord.errors.DiscordServerError: 500 Internal Server Error (error code: 0): 500: Internal Server Error
Ignoring exception in command None:
discord.ext.commands.errors.CommandNotFound: Command "moce" is not found
Ignoring exception in command None:
discord.ext.commands.errors.CommandNotFound: Command "d1c2" is not found
Ignoring exception in command None:
discord.ext.commands.errors.CommandNotFound: Command "avtive" is not found
Ignoring exception in command debug:
Traceback (most recent call last):
  File "/Users/benjamin/.pyenv/versions/3.9.0/lib/python3.9/site-packages/discord/ext/commands/core.py", line 85, in wrapped
    ret = await coro(*args, **kwargs)
  File "/Users/benjamin/Documents/Developer/Python/ChessBot/chessbot_remastered.py", line 380, in debug
    this_board = chess.Board(data[guild][str(game_num)]["fen"])
KeyError: '-1'

The above exception was the direct cause of the following exception:

Traceback (most recent call last):
  File "/Users/benjamin/.pyenv/versions/3.9.0/lib/python3.9/site-packages/discord/ext/commands/bot.py", line 903, in invoke
    await ctx.command.invoke(ctx)
  File "/Users/benjamin/.pyenv/versions/3.9.0/lib/python3.9/site-packages/discord/ext/commands/core.py", line 859, in invoke
    await injected(*ctx.args, **ctx.kwargs)
  File "/Users/benjamin/.pyenv/versions/3.9.0/lib/python3.9/site-packages/discord/ext/commands/core.py", line 94, in wrapped
    raise CommandInvokeError(exc) from exc
discord.ext.commands.errors.CommandInvokeError: Command raised an exception: KeyError: '-1'
online
online
online
online
online
online
online
online
online
online
online
online
online
online
online
online
online
online
online
online
online
online
online
online
online
online
